<robot name = "robot">
    <link name="Head">
        <inertial>
            <origin xyz="0 0 1" rpy="0 0 0"/>
            <mass value="1" />
            <inertia ixx="100" ixy="0" ixz="0" iyy="100" iyz="0" izz="100" />
        </inertial>
        <visual>
            <origin xyz="0 0 1" rpy="0 0 0"/>
            <geometry>
                <box size="1 1 2" />
            </geometry>
            <material name="Cyan">
                <color rgba="0 1.0 1.0 1.0"/>
            </material>
        </visual>
        <collision>
            <origin xyz="0 0 1" rpy="0 0 0"/>
            <geometry>
                <box size="1 1 2" />
            </geometry>
        </collision>
    </link>
    <joint name="Head_Neck1" type="revolute">
       <parent link="Head"/>
       <child  link="Neck1"/>
       <origin rpy="0 0 0" xyz="0.5 0 1" />
       <axis xyz="0 1 0"/>
       <limit effort="0.0" lower="-3.14159" upper="3.14159" velocity="0.0"/>
    </joint>
    <link name="Neck1">
        <inertial>
            <origin xyz="0.125 0 0" rpy="0 0 0"/>
            <mass value="1" />
            <inertia ixx="100" ixy="0" ixz="0" iyy="100" iyz="0" izz="100" />
        </inertial>
        <visual>
            <origin xyz="0.125 0 0" rpy="0 0 0"/>
            <geometry>
                <box size="0.25 0.15 0.15" />
            </geometry>
            <material name="Cyan">
                <color rgba="0 1.0 1.0 1.0"/>
            </material>
        </visual>
        <collision>
            <origin xyz="0.125 0 0" rpy="0 0 0"/>
            <geometry>
                <box size="0.25 0.15 0.15" />
            </geometry>
        </collision>
    </link>
    <joint name="Neck1_Abdomen1" type="revolute">
       <parent link="Neck1"/>
       <child  link="Abdomen1"/>
       <origin rpy="0 0 0" xyz="0.25 0 0" />
       <axis xyz="0 1 0"/>
       <limit effort="0.0" lower="-3.14159" upper="3.14159" velocity="0.0"/>
    </joint>
    <link name="Abdomen1">
        <inertial>
            <origin xyz="0.5 0 0" rpy="0 0 0"/>
            <mass value="1" />
            <inertia ixx="100" ixy="0" ixz="0" iyy="100" iyz="0" izz="100" />
        </inertial>
        <visual>
            <origin xyz="0.5 0 0" rpy="0 0 0"/>
            <geometry>
                <box size="1 1 2" />
            </geometry>
            <material name="Cyan">
                <color rgba="0 1.0 1.0 1.0"/>
            </material>
        </visual>
        <collision>
            <origin xyz="0.5 0 0" rpy="0 0 0"/>
            <geometry>
                <box size="1 1 2" />
            </geometry>
        </collision>
    </link>
    <joint name="Abdomen1_Neck2" type="revolute">
       <parent link="Abdomen1"/>
       <child  link="Neck2"/>
       <origin rpy="0 0 0" xyz="1 0 0" />
       <axis xyz="0 1 0"/>
       <limit effort="0.0" lower="-3.14159" upper="3.14159" velocity="0.0"/>
    </joint>
    <link name="Neck2">
        <inertial>
            <origin xyz="0.125 0 0" rpy="0 0 0"/>
            <mass value="1" />
            <inertia ixx="100" ixy="0" ixz="0" iyy="100" iyz="0" izz="100" />
        </inertial>
        <visual>
            <origin xyz="0.125 0 0" rpy="0 0 0"/>
            <geometry>
                <box size="0.25 0.15 0.15" />
            </geometry>
            <material name="Cyan">
                <color rgba="0 1.0 1.0 1.0"/>
            </material>
        </visual>
        <collision>
            <origin xyz="0.125 0 0" rpy="0 0 0"/>
            <geometry>
                <box size="0.25 0.15 0.15" />
            </geometry>
        </collision>
    </link>
    <joint name="Neck2_Abdomen2" type="revolute">
       <parent link="Neck2"/>
       <child  link="Abdomen2"/>
       <origin rpy="0 0 0" xyz="0.25 0 0" />
       <axis xyz="0 1 0"/>
       <limit effort="0.0" lower="-3.14159" upper="3.14159" velocity="0.0"/>
    </joint>
    <link name="Abdomen2">
        <inertial>
            <origin xyz="0.5 0 0" rpy="0 0 0"/>
            <mass value="1" />
            <inertia ixx="100" ixy="0" ixz="0" iyy="100" iyz="0" izz="100" />
        </inertial>
        <visual>
            <origin xyz="0.5 0 0" rpy="0 0 0"/>
            <geometry>
                <box size="1 1 2" />
            </geometry>
            <material name="Cyan">
                <color rgba="0 1.0 1.0 1.0"/>
            </material>
        </visual>
        <collision>
            <origin xyz="0.5 0 0" rpy="0 0 0"/>
            <geometry>
                <box size="1 1 2" />
            </geometry>
        </collision>
    </link>
    <joint name="Abdomen2_Neck3" type="revolute">
       <parent link="Abdomen2"/>
       <child  link="Neck3"/>
       <origin rpy="0 0 0" xyz="1 0 0" />
       <axis xyz="0 1 0"/>
       <limit effort="0.0" lower="-3.14159" upper="3.14159" velocity="0.0"/>
    </joint>
    <link name="Neck3">
        <inertial>
            <origin xyz="0.125 0 0" rpy="0 0 0"/>
            <mass value="1" />
            <inertia ixx="100" ixy="0" ixz="0" iyy="100" iyz="0" izz="100" />
        </inertial>
        <visual>
            <origin xyz="0.125 0 0" rpy="0 0 0"/>
            <geometry>
                <box size="0.25 0.15 0.15" />
            </geometry>
            <material name="Cyan">
                <color rgba="0 1.0 1.0 1.0"/>
            </material>
        </visual>
        <collision>
            <origin xyz="0.125 0 0" rpy="0 0 0"/>
            <geometry>
                <box size="0.25 0.15 0.15" />
            </geometry>
        </collision>
    </link>
    <joint name="Neck3_Abdomen3" type="revolute">
       <parent link="Neck3"/>
       <child  link="Abdomen3"/>
       <origin rpy="0 0 0" xyz="0.25 0 0" />
       <axis xyz="0 1 0"/>
       <limit effort="0.0" lower="-3.14159" upper="3.14159" velocity="0.0"/>
    </joint>
    <link name="Abdomen3">
        <inertial>
            <origin xyz="0.5 0 0" rpy="0 0 0"/>
            <mass value="1" />
            <inertia ixx="100" ixy="0" ixz="0" iyy="100" iyz="0" izz="100" />
        </inertial>
        <visual>
            <origin xyz="0.5 0 0" rpy="0 0 0"/>
            <geometry>
                <box size="1 1 2" />
            </geometry>
            <material name="Cyan">
                <color rgba="0 1.0 1.0 1.0"/>
            </material>
        </visual>
        <collision>
            <origin xyz="0.5 0 0" rpy="0 0 0"/>
            <geometry>
                <box size="1 1 2" />
            </geometry>
        </collision>
    </link>
</robot>